Workbook

Sheet LISTAS + README
A1: README
A2: 1. Llena los datos del proyecto en la hoja TRABAJO.
A3: 3. En 'Estado' define si cada ítem es Excluido, Supuesto o Revisión.
A4: 4. En 'Mostrar al cliente', deja Sí solo en lo que quieras que aparezca en PRESENTACION.
A5: 5. Si hay alguna exclusión o supuesto que precisar, hazlo directamente en la hoja PRESENTACION.
A6: 6. La hoja PRESENTACION usa fórmulas compatibles con Excel clásico.
A10: LISTA_ESTADOS | C10: LISTA_SI_NO | E10: LISTA_CATEGORIAS | H10: BIBLIOTECA_BASE
A11: Excluido | C11: Sí | E11: Exclusiones generales | H11: Categoría | I11: Ítem | J11: Texto base sugerido
A12: Supuesto | C12: No | E12: Exclusiones específicas | H12: Exclusiones generales | I12: Trámites y licencias | J12: No incluye gestión municipal, licencias ni aprobación ante entidades.
A13: Revisión | E13: Supuestos técnicos | H13: Exclusiones generales | I13: Tasas y derechos | J13: No incluye pagos por tasas, derechos, impuestos ni costos municipales.
E14: Supuestos comerciales | H14: Exclusiones generales | I14: Topografía / estudios previos | J14: No incluye levantamiento topográfico, mecánica de suelos ni estudios especializados.
E15: Supuestos de plazo | H15: Exclusiones generales | I15: Especialidades | J15: No incluye desarrollo de estructuras, sanitarias, eléctricas, HVAC u otras especialidades.
E16: Eventos de recotización | H16: Exclusiones generales | I16: Mobiliario y equipamiento | J16: No incluye mobiliario suelto, equipamiento ni compras directas.
H17: Exclusiones generales | I17: Paisajismo / señalética / branding | J17: No incluye diseño de paisaje, branding, señalética ni gráfica ambiental.
H18: Exclusiones generales | I18: Renders extra / impresiones | J18: No incluye visualizaciones adicionales ni impresiones físicas fuera de lo acordado.
H19: Exclusiones generales | I19: Supervisión permanente / ejecución | J19: No incluye ejecución de obra, administración integral ni presencia permanente en campo.
H20: Exclusiones específicas | I20: Intervenciones fuera del área definida | J20: No incluye áreas no contempladas expresamente en el alcance base.
H21: Exclusiones específicas | I21: Requerimientos no informados al inicio | J21: No incluye exigencias o partidas que no hayan sido informadas al momento de cotizar.
H22: Supuestos técnicos | I22: Información base entregada por el cliente | J22: Se asume que medidas, planos y data base entregada por el cliente son suficientes y confiables.
H23: Supuestos técnicos | I23: Condiciones existentes regulares | J23: Se asume que el inmueble no presenta contingencias ocultas no visibles al momento de la propuesta.
H24: Supuestos técnicos | I24: Acceso y levantamiento | J24: Se asume acceso razonable al inmueble para visitas, levantamiento y validaciones.
H25: Supuestos comerciales | I25: Número de reuniones | J25: Se asume un número acotado de reuniones según la cotización aprobada.
H26: Supuestos comerciales | I26: Número de revisiones | J26: Se asume un máximo de rondas de cambios/revisión según lo ofertado.
H27: Supuestos comerciales | I27: Aprobaciones por etapa | J27: Se asume que el cliente valida cada etapa antes de avanzar a la siguiente.
H28: Supuestos comerciales | I28: Cambios fuera de alcance | J28: Todo cambio fuera del alcance aprobado se cotiza aparte.
... H35: Eventos de recotización | I35: Información base incorrecta | J35: Errores u omisiones en la información base que alteren el servicio generan ajuste económico/plazo.

Sheet TRABAJO
A1: PLANTILLA DE EXCLUSIONES Y SUPUESTOS
A3: Cliente
A4: Proyecto
A5: Código
A6: Fecha
A7: Responsable
A9: INSTRUCCIÓN | B9: Usa solo 'Mostrar al cliente' para decidir qué ítems aparecen en la presentación.
A11: Categoría | B11: Ítem | C11: Estado | D11: Mostrar al cliente | E11: Prioridad | F11: Texto final para cliente | G11: Ítem | H11: Categoría | I11: Texto base | J11: Seq_Excluido | K11: Seq_Supuesto | L11: Seq_Revision
A12: Exclusiones generales | B12: Trámites y licencias | C12: Excluido | D12: Sí | E12: Media | F12: =VLOOKUP(B12,$G$12:$I$35,3,FALSE) -> No incluye gestión municipal, licencias ni aprobación ante entidades. | G12: Trámites y licencias | H12: Exclusiones generales | I12: No incluye gestión municipal, licencias ni aprobación ante entidades. | J12: =IF(AND(OR($D12="Sí",$D12="Si",$D12="SI"),$C12="Excluido"),SUMPRODUCT((($D$12:$D12="Sí")+($D$12:$D12="Si")+($D$12:$D12="SI"))*($C$12:$C12="Excluido")),"") -> 1 | K12: =IF(AND(OR($D12="Sí",$D12="Si",$D12="SI"),$C12="Supuesto"),SUMPRODUCT((($D$12:$D12="Sí")+($D$12:$D12="Si")+($D$12:$D12="SI"))*($C$12:$C12="Supuesto")),"") | L12: =IF(AND(OR($D12="Sí",$D12="Si",$D12="SI"),$C12="Revisión"),SUMPRODUCT((($D$12:$D12="Sí")+($D$12:$D12="Si")+($D$12:$D12="SI"))*($C$12:$C12="Revisión")),"")
A13: Exclusiones generales | B13: Tasas y derechos | C13: Excluido | D13: Sí | E13: Media | F13: =VLOOKUP(B13,$G$12:$I$35,3,FALSE) -> No incluye pagos por tasas, derechos, impuestos ni costos municipales. | G13: Tasas y derechos | H13: Exclusiones generales | I13: No incluye pagos por tasas, derechos, impuestos ni costos municipales. | J13: =IF(AND(OR($D13="Sí",$D13="Si",$D13="SI"),$C13="Excluido"),SUMPRODUCT((($D$12:$D13="Sí")+($D$12:$D13="Si")+($D$12:$D13="SI"))*($C$12:$C13="Excluido")),"") -> 2 | K13: =IF(AND(OR($D13="Sí",$D13="Si",$D13="SI"),$C13="Supuesto"),SUMPRODUCT((($D$12:$D13="Sí")+($D$12:$D13="Si")+($D$12:$D13="SI"))*($C$12:$C13="Supuesto")),"") | L13: =IF(AND(OR($D13="Sí",$D13="Si",$D13="SI"),$C13="Revisión"),SUMPRODUCT((($D$12:$D13="Sí")+($D$12:$D13="Si")+($D$12:$D13="SI"))*($C$12:$C13="Revisión")),"")
A14: Exclusiones generales | B14: Topografía / estudios previos | C14: Excluido | D14: No | E14: Media | F14: =VLOOKUP(B14,$G$12:$I$35,3,FALSE) -> No incluye levantamiento topográfico, mecánica de suelos ni estudios especializados. | G14: Topografía / estudios previos | H14: Exclusiones generales | I14: No incluye levantamiento topográfico, mecánica de suelos ni estudios especializados. | J14: =IF(AND(OR($D14="Sí",$D14="Si",$D14="SI"),$C14="Excluido"),SUMPRODUCT((($D$12:$D14="Sí")+($D$12:$D14="Si")+($D$12:$D14="SI"))*($C$12:$C14="Excluido")),"") | K14: =IF(AND(OR($D14="Sí",$D14="Si",$D14="SI"),$C14="Supuesto"),SUMPRODUCT((($D$12:$D14="Sí")+($D$12:$D14="Si")+($D$12:$D14="SI"))*($C$12:$C14="Supuesto")),"") | L14: =IF(AND(OR($D14="Sí",$D14="Si",$D14="SI"),$C14="Revisión"),SUMPRODUCT((($D$12:$D14="Sí")+($D$12:$D14="Si")+($D$12:$D14="SI"))*($C$12:$C14="Revisión")),"")
A15: Exclusiones generales | B15: Especialidades | C15: Excluido | D15: No | E15: Media | F15: =VLOOKUP(B15,$G$12:$I$35,3,FALSE) -> No incluye desarrollo de estructuras, sanitarias, eléctricas, HVAC u otras especialidades. | G15: Especialidades | H15: Exclusiones generales | I15: No incluye desarrollo de estructuras, sanitarias, eléctricas, HVAC u otras especialidades. | J15: =IF(AND(OR($D15="Sí",$D15="Si",$D15="SI"),$C15="Excluido"),SUMPRODUCT((($D$12:$D15="Sí")+($D$12:$D15="Si")+($D$12:$D15="SI"))*($C$12:$C15="Excluido")),"") | K15: =IF(AND(OR($D15="Sí",$D15="Si",$D15="SI"),$C15="Supuesto"),SUMPRODUCT((($D$12:$D15="Sí")+($D$12:$D15="Si")+($D$12:$D15="SI"))*($C$12:$C15="Supuesto")),"") | L15: =IF(AND(OR($D15="Sí",$D15="Si",$D15="SI"),$C15="Revisión"),SUMPRODUCT((($D$12:$D15="Sí")+($D$12:$D15="Si")+($D$12:$D15="SI"))*($C$12:$C15="Revisión")),"")
A16: Exclusiones generales | B16: Mobiliario y equipamiento | C16: Excluido | D16: No | E16: Media | F16: =VLOOKUP(B16,$G$12:$I$35,3,FALSE) -> No incluye mobiliario suelto, equipamiento ni compras directas. | G16: Mobiliario y equipamiento | H16: Exclusiones generales | I16: No incluye mobiliario suelto, equipamiento ni compras directas. | J16: =IF(AND(OR($D16="Sí",$D16="Si",$D16="SI"),$C16="Excluido"),SUMPRODUCT((($D$12:$D16="Sí")+($D$12:$D16="Si")+($D$12:$D16="SI"))*($C$12:$C16="Excluido")),"") | K16: =IF(AND(OR($D16="Sí",$D16="Si",$D16="SI"),$C16="Supuesto"),SUMPRODUCT((($D$12:$D16="Sí")+($D$12:$D16="Si")+($D$12:$D16="SI"))*($C$12:$C16="Supuesto")),"") | L16: =IF(AND(OR($D16="Sí",$D16="Si",$D16="SI"),$C16="Revisión"),SUMPRODUCT((($D$12:$D16="Sí")+($D$12:$D16="Si")+($D$12:$D16="SI"))*($C$12:$C16="Revisión")),"")
A17: Exclusiones generales | B17: Paisajismo / señalética / branding | C17: Excluido | D17: No | E17: Media | F17: =VLOOKUP(B17,$G$12:$I$35,3,FALSE) -> No incluye diseño de paisaje, branding, señalética ni gráfica ambiental. | G17: Paisajismo / señalética / branding | H17: Exclusiones generales | I17: No incluye diseño de paisaje, branding, señalética ni gráfica ambiental. | J17: =IF(AND(OR($D17="Sí",$D17="Si",$D17="SI"),$C17="Excluido"),SUMPRODUCT((($D$12:$D17="Sí")+($D$12:$D17="Si")+($D$12:$D17="SI"))*($C$12:$C17="Excluido")),"") | K17: =IF(AND(OR($D17="Sí",$D17="Si",$D17="SI"),$C17="Supuesto"),SUMPRODUCT((($D$12:$D17="Sí")+($D$12:$D17="Si")+($D$12:$D17="SI"))*($C$12:$C17="Supuesto")),"") | L17: =IF(AND(OR($D17="Sí",$D17="Si",$D17="SI"),$C17="Revisión"),SUMPRODUCT((($D$12:$D17="Sí")+($D$12:$D17="Si")+($D$12:$D17="SI"))*($C$12:$C17="Revisión")),"")
A18: Exclusiones generales | B18: Renders extra / impresiones | C18: Excluido | D18: No | E18: Media | F18: =VLOOKUP(B18,$G$12:$I$35,3,FALSE) -> No incluye visualizaciones adicionales ni impresiones físicas fuera de lo acordado. | G18: Renders extra / impresiones | H18: Exclusiones generales | I18: No incluye visualizaciones adicionales ni impresiones físicas fuera de lo acordado. | J18: =IF(AND(OR($D18="Sí",$D18="Si",$D18="SI"),$C18="Excluido"),SUMPRODUCT((($D$12:$D18="Sí")+($D$12:$D18="Si")+($D$12:$D18="SI"))*($C$12:$C18="Excluido")),"") | K18: =IF(AND(OR($D18="Sí",$D18="Si",$D18="SI"),$C18="Supuesto"),SUMPRODUCT((($D$12:$D18="Sí")+($D$12:$D18="Si")+($D$12:$D18="SI"))*($C$12:$C18="Supuesto")),"") | L18: =IF(AND(OR($D18="Sí",$D18="Si",$D18="SI"),$C18="Revisión"),SUMPRODUCT((($D$12:$D18="Sí")+($D$12:$D18="Si")+($D$12:$D18="SI"))*($C$12:$C18="Revisión")),"")
A19: Exclusiones generales | B19: Supervisión permanente / ejecución | C19: Excluido | D19: Sí | E19: Media | F19: =VLOOKUP(B19,$G$12:$I$35,3,FALSE) -> No incluye ejecución de obra, administración integral ni presencia permanente en campo. | G19: Supervisión permanente / ejecución | H19: Exclusiones generales | I19: No incluye ejecución de obra, administración integral ni presencia permanente en campo. | J19: =IF(AND(OR($D19="Sí",$D19="Si",$D19="SI"),$C19="Excluido"),SUMPRODUCT((($D$12:$D19="Sí")+($D$12:$D19="Si")+($D$12:$D19="SI"))*($C$12:$C19="Excluido")),"") -> 3 | K19: =IF(AND(OR($D19="Sí",$D19="Si",$D19="SI"),$C19="Supuesto"),SUMPRODUCT((($D$12:$D19="Sí")+($D$12:$D19="Si")+($D$12:$D19="SI"))*($C$12:$C19="Supuesto")),"") | L19: =IF(AND(OR($D19="Sí",$D19="Si",$D19="SI"),$C19="Revisión"),SUMPRODUCT((($D$12:$D19="Sí")+($D$12:$D19="Si")+($D$12:$D19="SI"))*($C$12:$C19="Revisión")),"")
A20: Exclusiones específicas | B20: Intervenciones fuera del área definida | C20: Excluido | D20: Sí | E20: Media | F20: =VLOOKUP(B20,$G$12:$I$35,3,FALSE) -> No incluye áreas no contempladas expresamente en el alcance base. | G20: Intervenciones fuera del área definida | H20: Exclusiones específicas | I20: No incluye áreas no contempladas expresamente en el alcance base. | J20: =IF(AND(OR($D20="Sí",$D20="Si",$D20="SI"),$C20="Excluido"),SUMPRODUCT((($D$12:$D20="Sí")+($D$12:$D20="Si")+($D$12:$D20="SI"))*($C$12:$C20="Excluido")),"") -> 4 | K20: =IF(AND(OR($D20="Sí",$D20="Si",$D20="SI"),$C20="Supuesto"),SUMPRODUCT((($D$12:$D20="Sí")+($D$12:$D20="Si")+($D$12:$D20="SI"))*($C$12:$C20="Supuesto")),"") | L20: =IF(AND(OR($D20="Sí",$D20="Si",$D20="SI"),$C20="Revisión"),SUMPRODUCT((($D$12:$D20="Sí")+($D$12:$D20="Si")+($D$12:$D20="SI"))*($C$12:$C20="Revisión")),"")
A21: Exclusiones específicas | B21: Requerimientos no informados al inicio | C21: Excluido | D21: Sí | E21: Media | F21: =VLOOKUP(B21,$G$12:$I$35,3,FALSE) -> No incluye exigencias o partidas que no hayan sido informadas al momento de cotizar. | G21: Requerimientos no informados al inicio | H21: Exclusiones específicas | I21: No incluye exigencias o partidas que no hayan sido informadas al momento de cotizar. | J21: =IF(AND(OR($D21="Sí",$D21="Si",$D21="SI"),$C21="Excluido"),SUMPRODUCT((($D$12:$D21="Sí")+($D$12:$D21="Si")+($D$12:$D21="SI"))*($C$12:$C21="Excluido")),"") -> 5 | K21: =IF(AND(OR($D21="Sí",$D21="Si",$D21="SI"),$C21="Supuesto"),SUMPRODUCT((($D$12:$D21="Sí")+($D$12:$D21="Si")+($D$12:$D21="SI"))*($C$12:$C21="Supuesto")),"") | L21: =IF(AND(OR($D21="Sí",$D21="Si",$D21="SI"),$C21="Revisión"),SUMPRODUCT((($D$12:$D21="Sí")+($D$12:$D21="Si")+($D$12:$D21="SI"))*($C$12:$C21="Revisión")),"")
A22: Supuestos técnicos | B22: Información base entregada por el cliente | C22: Supuesto | D22: No | E22: Media | F22: =VLOOKUP(B22,$G$12:$I$35,3,FALSE) -> Se asume que medidas, planos y data base entregada por el cliente son suficientes y confiables. | G22: Información base entregada por el cliente | H22: Supuestos técnicos | I22: Se asume que medidas, planos y data base entregada por el cliente son suficientes y confiables. | J22: =IF(AND(OR($D22="Sí",$D22="Si",$D22="SI"),$C22="Excluido"),SUMPRODUCT((($D$12:$D22="Sí")+($D$12:$D22="Si")+($D$12:$D22="SI"))*($C$12:$C22="Excluido")),"") | K22: =IF(AND(OR($D22="Sí",$D22="Si",$D22="SI"),$C22="Supuesto"),SUMPRODUCT((($D$12:$D22="Sí")+($D$12:$D22="Si")+($D$12:$D22="SI"))*($C$12:$C22="Supuesto")),"") | L22: =IF(AND(OR($D22="Sí",$D22="Si",$D22="SI"),$C22="Revisión"),SUMPRODUCT((($D$12:$D22="Sí")+($D$12:$D22="Si")+($D$12:$D22="SI"))*($C$12:$C22="Revisión")),"")
A23: Supuestos técnicos | B23: Condiciones existentes regulares | C23: Supuesto | D23: Sí | E23: Media | F23: =VLOOKUP(B23,$G$12:$I$35,3,FALSE) -> Se asume que el inmueble no presenta contingencias ocultas no visibles al momento de la propuesta. | G23: Condiciones existentes regulares | H23: Supuestos técnicos | I23: Se asume que el inmueble no presenta contingencias ocultas no visibles al momento de la propuesta. | J23: =IF(AND(OR($D23="Sí",$D23="Si",$D23="SI"),$C23="Excluido"),SUMPRODUCT((($D$12:$D23="Sí")+($D$12:$D23="Si")+($D$12:$D23="SI"))*($C$12:$C23="Excluido")),"") | K23: =IF(AND(OR($D23="Sí",$D23="Si",$D23="SI"),$C23="Supuesto"),SUMPRODUCT((($D$12:$D23="Sí")+($D$12:$D23="Si")+($D$12:$D23="SI"))*($C$12:$C23="Supuesto")),"") -> 1 | L23: =IF(AND(OR($D23="Sí",$D23="Si",$D23="SI"),$C23="Revisión"),SUMPRODUCT((($D$12:$D23="Sí")+($D$12:$D23="Si")+($D$12:$D23="SI"))*($C$12:$C23="Revisión")),"")
... A35: Eventos de recotización | B35: Información base incorrecta | C35: Revisión | D35: No | E35: Media | F35: =VLOOKUP(B35,$G$12:$I$35,3,FALSE) -> Errores u omisiones en la información base que alteren el servicio generan ajuste económico/plazo. | G35: Información base incorrecta | H35: Eventos de recotización | I35: Errores u omisiones en la información base que alteren el servicio generan ajuste económico/plazo. | J35: =IF(AND(OR($D35="Sí",$D35="Si",$D35="SI"),$C35="Excluido"),SUMPRODUCT((($D$12:$D35="Sí")+($D$12:$D35="Si")+($D$12:$D35="SI"))*($C$12:$C35="Excluido")),"") | K35: =IF(AND(OR($D35="Sí",$D35="Si",$D35="SI"),$C35="Supuesto"),SUMPRODUCT((($D$12:$D35="Sí")+($D$12:$D35="Si")+($D$12:$D35="SI"))*($C$12:$C35="Supuesto")),"") | L35: =IF(AND(OR($D35="Sí",$D35="Si",$D35="SI"),$C35="Revisión"),SUMPRODUCT((($D$12:$D35="Sí")+($D$12:$D35="Si")+($D$12:$D35="SI"))*($C$12:$C35="Revisión")),"")

Sheet PRESENTACION
A1: EXCLUSIONES Y SUPUESTOS
A3: Cliente | B3: =TRABAJO!B3 -> 0
A4: Proyecto | B4: =TRABAJO!B4 -> 0
A5: Código | B5: =TRABAJO!B5 -> 0
A6: Fecha | B6: =TRABAJO!B6 -> 0
A7: Responsable | B7: =TRABAJO!B7 -> 0
A9: OBJETO
A10: Este documento delimita las exclusiones y los supuestos base considerados para la oferta o propuesta económica del encargo.
A12: EXCLUSIONES
A13: =IFERROR(INDEX(TRABAJO!$C$12:$C$35,MATCH(1,TRABAJO!$J$12:$J$35,0)),"") -> Excluido | B13: =IF($A13="","",INDEX(TRABAJO!$B$12:$B$35,MATCH(1,TRABAJO!$J$12:$J$35,0))) -> Trámites y licencias | C13: =IF($A13="","",INDEX(TRABAJO!$F$12:$F$35,MATCH(1,TRABAJO!$J$12:$J$35,0))) -> No incluye gestión municipal, licencias ni aprobación ante entidades.
A14: =IFERROR(INDEX(TRABAJO!$C$12:$C$35,MATCH(2,TRABAJO!$J$12:$J$35,0)),"") -> Excluido | B14: =IF($A14="","",INDEX(TRABAJO!$B$12:$B$35,MATCH(2,TRABAJO!$J$12:$J$35,0))) -> Tasas y derechos | C14: =IF($A14="","",INDEX(TRABAJO!$F$12:$F$35,MATCH(2,TRABAJO!$J$12:$J$35,0))) -> No incluye pagos por tasas, derechos, impuestos ni costos municipales.
A15: =IFERROR(INDEX(TRABAJO!$C$12:$C$35,MATCH(3,TRABAJO!$J$12:$J$35,0)),"") -> Excluido | B15: =IF($A15="","",INDEX(TRABAJO!$B$12:$B$35,MATCH(3,TRABAJO!$J$12:$J$35,0))) -> Supervisión permanente / ejecución | C15: =IF($A15="","",INDEX(TRABAJO!$F$12:$F$35,MATCH(3,TRABAJO!$J$12:$J$35,0))) -> No incluye ejecución de obra, administración integral ni presencia permanente en campo.
A16: =IFERROR(INDEX(TRABAJO!$C$12:$C$35,MATCH(4,TRABAJO!$J$12:$J$35,0)),"") -> Excluido | B16: =IF($A16="","",INDEX(TRABAJO!$B$12:$B$35,MATCH(4,TRABAJO!$J$12:$J$35,0))) -> Intervenciones fuera del área definida | C16: =IF($A16="","",INDEX(TRABAJO!$F$12:$F$35,MATCH(4,TRABAJO!$J$12:$J$35,0))) -> No incluye áreas no contempladas expresamente en el alcance base.
A17: =IFERROR(INDEX(TRABAJO!$C$12:$C$35,MATCH(5,TRABAJO!$J$12:$J$35,0)),"") -> Excluido | B17: =IF($A17="","",INDEX(TRABAJO!$B$12:$B$35,MATCH(5,TRABAJO!$J$12:$J$35,0))) -> Requerimientos no informados al inicio | C17: =IF($A17="","",INDEX(TRABAJO!$F$12:$F$35,MATCH(5,TRABAJO!$J$12:$J$35,0))) -> No incluye exigencias o partidas que no hayan sido informadas al momento de cotizar.
A18: =IFERROR(INDEX(TRABAJO!$C$12:$C$35,MATCH(6,TRABAJO!$J$12:$J$35,0)),"") | B18: =IF($A18="","",INDEX(TRABAJO!$B$12:$B$35,MATCH(6,TRABAJO!$J$12:$J$35,0))) | C18: =IF($A18="","",INDEX(TRABAJO!$F$12:$F$35,MATCH(6,TRABAJO!$J$12:$J$35,0)))
A19: =IFERROR(INDEX(TRABAJO!$C$12:$C$35,MATCH(7,TRABAJO!$J$12:$J$35,0)),"") | B19: =IF($A19="","",INDEX(TRABAJO!$B$12:$B$35,MATCH(7,TRABAJO!$J$12:$J$35,0))) | C19: =IF($A19="","",INDEX(TRABAJO!$F$12:$F$35,MATCH(7,TRABAJO!$J$12:$J$35,0)))
A20: =IFERROR(INDEX(TRABAJO!$C$12:$C$35,MATCH(8,TRABAJO!$J$12:$J$35,0)),"") | B20: =IF($A20="","",INDEX(TRABAJO!$B$12:$B$35,MATCH(8,TRABAJO!$J$12:$J$35,0))) | C20: =IF($A20="","",INDEX(TRABAJO!$F$12:$F$35,MATCH(8,TRABAJO!$J$12:$J$35,0)))
A21: =IFERROR(INDEX(TRABAJO!$C$12:$C$35,MATCH(9,TRABAJO!$J$12:$J$35,0)),"") | B21: =IF($A21="","",INDEX(TRABAJO!$B$12:$B$35,MATCH(9,TRABAJO!$J$12:$J$35,0))) | C21: =IF($A21="","",INDEX(TRABAJO!$F$12:$F$35,MATCH(9,TRABAJO!$J$12:$J$35,0)))
A22: =IFERROR(INDEX(TRABAJO!$C$12:$C$35,MATCH(10,TRABAJO!$J$12:$J$35,0)),"") | B22: =IF($A22="","",INDEX(TRABAJO!$B$12:$B$35,MATCH(10,TRABAJO!$J$12:$J$35,0))) | C22: =IF($A22="","",INDEX(TRABAJO!$F$12:$F$35,MATCH(10,TRABAJO!$J$12:$J$35,0)))
A24: SUPUESTOS
A25: =IFERROR(INDEX(TRABAJO!$C$12:$C$35,MATCH(1,TRABAJO!$K$12:$K$35,0)),"") -> Supuesto | B25: =IF($A25="","",INDEX(TRABAJO!$B$12:$B$35,MATCH(1,TRABAJO!$K$12:$K$35,0))) -> Condiciones existentes regulares | C25: =IF($A25="","",INDEX(TRABAJO!$F$12:$F$35,MATCH(1,TRABAJO!$K$12:$K$35,0))) -> Se asume que el inmueble no presenta contingencias ocultas no visibles al momento de la propuesta.
A26: =IFERROR(INDEX(TRABAJO!$C$12:$C$35,MATCH(2,TRABAJO!$K$12:$K$35,0)),"") -> Supuesto | B26: =IF($A26="","",INDEX(TRABAJO!$B$12:$B$35,MATCH(2,TRABAJO!$K$12:$K$35,0))) -> Número de revisiones | C26: =IF($A26="","",INDEX(TRABAJO!$F$12:$F$35,MATCH(2,TRABAJO!$K$12:$K$35,0))) -> Se asume un máximo de rondas de cambios/revisión según lo ofertado.
A27: =IFERROR(INDEX(TRABAJO!$C$12:$C$35,MATCH(3,TRABAJO!$K$12:$K$35,0)),"") -> Supuesto | B27: =IF($A27="","",INDEX(TRABAJO!$B$12:$B$35,MATCH(3,TRABAJO!$K$12:$K$35,0))) -> Aprobaciones por etapa | C27: =IF($A27="","",INDEX(TRABAJO!$F$12:$F$35,MATCH(3,TRABAJO!$K$12:$K$35,0))) -> Se asume que el cliente valida cada etapa antes de avanzar a la siguiente.
A28: =IFERROR(INDEX(TRABAJO!$C$12:$C$35,MATCH(4,TRABAJO!$K$12:$K$35,0)),"") -> Supuesto | B28: =IF($A28="","",INDEX(TRABAJO!$B$12:$B$35,MATCH(4,TRABAJO!$K$12:$K$35,0))) -> Cambios fuera de alcance | C28: =IF($A28="","",INDEX(TRABAJO!$F$12:$F$35,MATCH(4,TRABAJO!$K$12:$K$35,0))) -> Todo cambio fuera del alcance aprobado se cotiza aparte.
A29: =IFERROR(INDEX(TRABAJO!$C$12:$C$35,MATCH(5,TRABAJO!$K$12:$K$35,0)),"") -> Supuesto | B29: =IF($A29="","",INDEX(TRABAJO!$B$12:$B$35,MATCH(5,TRABAJO!$K$12:$K$35,0))) -> Inicio sujeto a adelanto o aprobación | C29: =IF($A29="","",INDEX(TRABAJO!$F$12:$F$35,MATCH(5,TRABAJO!$K$12:$K$35,0))) -> El inicio corre desde la aprobación formal y/o pago inicial.
A30: =IFERROR(INDEX(TRABAJO!$C$12:$C$35,MATCH(6,TRABAJO!$K$12:$K$35,0)),"") -> Supuesto | B30: =IF($A30="","",INDEX(TRABAJO!$B$12:$B$35,MATCH(6,TRABAJO!$K$12:$K$35,0))) -> Retroalimentación oportuna del cliente | C30: =IF($A30="","",INDEX(TRABAJO!$F$12:$F$35,MATCH(6,TRABAJO!$K$12:$K$35,0))) -> Los plazos suponen respuestas y validaciones del cliente dentro de tiempos razonables.
A31: =IFERROR(INDEX(TRABAJO!$C$12:$C$35,MATCH(7,TRABAJO!$K$12:$K$35,0)),"") -> Supuesto | B31: =IF($A31="","",INDEX(TRABAJO!$B$12:$B$35,MATCH(7,TRABAJO!$K$12:$K$35,0))) -> Terceros y entidades externas | C31: =IF($A31="","",INDEX(TRABAJO!$F$12:$F$35,MATCH(7,TRABAJO!$K$12:$K$35,0))) -> No se consideran demoras atribuibles a terceros, proveedores, comités o entidades.
A32: =IFERROR(INDEX(TRABAJO!$C$12:$C$35,MATCH(8,TRABAJO!$K$12:$K$35,0)),"") | B32: =IF($A32="","",INDEX(TRABAJO!$B$12:$B$35,MATCH(8,TRABAJO!$K$12:$K$35,0))) | C32: =IF($A32="","",INDEX(TRABAJO!$F$12:$F$35,MATCH(8,TRABAJO!$K$12:$K$35,0)))
A33: =IFERROR(INDEX(TRABAJO!$C$12:$C$35,MATCH(9,TRABAJO!$K$12:$K$35,0)),"") | B33: =IF($A33="","",INDEX(TRABAJO!$B$12:$B$35,MATCH(9,TRABAJO!$K$12:$K$35,0))) | C33: =IF($A33="","",INDEX(TRABAJO!$F$12:$F$35,MATCH(9,TRABAJO!$K$12:$K$35,0)))
A34: =IFERROR(INDEX(TRABAJO!$C$12:$C$35,MATCH(10,TRABAJO!$K$12:$K$35,0)),"") | B34: =IF($A34="","",INDEX(TRABAJO!$B$12:$B$35,MATCH(10,TRABAJO!$K$12:$K$35,0))) | C34: =IF($A34="","",INDEX(TRABAJO!$F$12:$F$35,MATCH(10,TRABAJO!$K$12:$K$35,0)))
A36: EVENTOS QUE GENERAN RECOTIZACIÓN
A37: =IFERROR(INDEX(TRABAJO!$C$12:$C$35,MATCH(1,TRABAJO!$L$12:$L$35,0)),"") -> Revisión | B37: =IF($A37="","",INDEX(TRABAJO!$B$12:$B$35,MATCH(1,TRABAJO!$L$12:$L$35,0))) -> Cambio de alcance | C37: =IF($A37="","",INDEX(TRABAJO!$F$12:$F$35,MATCH(1,TRABAJO!$L$12:$L$35,0))) -> Cualquier cambio de alcance, área o nivel de detalle genera recotización.
A38: =IFERROR(INDEX(TRABAJO!$C$12:$C$35,MATCH(2,TRABAJO!$L$12:$L$35,0)),"") | B38: =IF($A38="","",INDEX(TRABAJO!$B$12:$B$35,MATCH(2,TRABAJO!$L$12:$L$35,0))) | C38: =IF($A38="","",INDEX(TRABAJO!$F$12:$F$35,MATCH(2,TRABAJO!$L$12:$L$35,0)))
A39: =IFERROR(INDEX(TRABAJO!$C$12:$C$35,MATCH(3,TRABAJO!$L$12:$L$35,0)),"") | B39: =IF($A39="","",INDEX(TRABAJO!$B$12:$B$35,MATCH(3,TRABAJO!$L$12:$L$35,0))) | C39: =IF($A39="","",INDEX(TRABAJO!$F$12:$F$35,MATCH(3,TRABAJO!$L$12:$L$35,0)))
A40: =IFERROR(INDEX(TRABAJO!$C$12:$C$35,MATCH(4,TRABAJO!$L$12:$L$35,0)),"") | B40: =IF($A40="","",INDEX(TRABAJO!$B$12:$B$35,MATCH(4,TRABAJO!$L$12:$L$35,0))) | C40: =IF($A40="","",INDEX(TRABAJO!$F$12:$F$35,MATCH(4,TRABAJO!$L$12:$L$35,0)))
A41: =IFERROR(INDEX(TRABAJO!$C$12:$C$35,MATCH(5,TRABAJO!$L$12:$L$35,0)),"") | B41: =IF($A41="","",INDEX(TRABAJO!$B$12:$B$35,MATCH(5,TRABAJO!$L$12:$L$35,0))) | C41: =IF($A41="","",INDEX(TRABAJO!$F$12:$F$35,MATCH(5,TRABAJO!$L$12:$L$35,0)))
A42: =IFERROR(INDEX(TRABAJO!$C$12:$C$35,MATCH(6,TRABAJO!$L$12:$L$35,0)),"") | B42: =IF($A42="","",INDEX(TRABAJO!$B$12:$B$35,MATCH(6,TRABAJO!$L$12:$L$35,0))) | C42: =IF($A42="","",INDEX(TRABAJO!$F$12:$F$35,MATCH(6,TRABAJO!$L$12:$L$35,0)))
A43: =IFERROR(INDEX(TRABAJO!$C$12:$C$35,MATCH(7,TRABAJO!$L$12:$L$35,0)),"") | B43: =IF($A43="","",INDEX(TRABAJO!$B$12:$B$35,MATCH(7,TRABAJO!$L$12:$L$35,0))) | C43: =IF($A43="","",INDEX(TRABAJO!$F$12:$F$35,MATCH(7,TRABAJO!$L$12:$L$35,0)))
A44: =IFERROR(INDEX(TRABAJO!$C$12:$C$35,MATCH(8,TRABAJO!$L$12:$L$35,0)),"") | B44: =IF($A44="","",INDEX(TRABAJO!$B$12:$B$35,MATCH(8,TRABAJO!$L$12:$L$35,0))) | C44: =IF($A44="","",INDEX(TRABAJO!$F$12:$F$35,MATCH(8,TRABAJO!$L$12:$L$35,0)))
A45: =IFERROR(INDEX(TRABAJO!$C$12:$C$35,MATCH(9,TRABAJO!$L$12:$L$35,0)),"") | B45: =IF($A45="","",INDEX(TRABAJO!$B$12:$B$35,MATCH(9,TRABAJO!$L$12:$L$35,0))) | C45: =IF($A45="","",INDEX(TRABAJO!$F$12:$F$35,MATCH(9,TRABAJO!$L$12:$L$35,0)))
...
