Workbook

Sheet LISTAS + README
A1: PROGRAMA ARQUITECTÓNICO — LISTAS + README
A3: 1) Completa IDENTIDAD, luego PROGRAMA ESPACIOS y CONDICIONANTES.
A4: 2) En PROGRAMA ESPACIOS llena solo celdas amarillas; el área total se calcula sola.
A5: 3) La tabla de áreas por zona y el gráfico se actualizan automáticamente.
A6: 4) PRESENTACION arma la ficha para adjuntar a propuesta o para validación con firma.
A8: LISTAS
A10: ZONAS | B10: Orden | D10: PRIORIDAD | F10: TIPO PROYECTO | H10: ESTADO ACTUAL
A11: Pública | B11: 1 | D11: Alta | F11: Remodelación | H11: Idea
A12: Privada | B12: 2 | D12: Media | F12: Arquitectura nueva | H12: Brief confirmado
A13: Servicio | B13: 3 | D13: Baja | F13: Interiorismo | H13: Diseño en curso
A14: Exterior | B14: 4 | F14: Oficina | H14: Expediente
A15: Técnica | B15: 5 | F15: Comercial | H15: Obra
A16: Comercial | B16: 6 | F16: Industrial pequeño | H16: Cerrado
A17: Común | B17: 7 | F17: Consultoría

Sheet IDENTIDAD
A1: IDENTIDAD — FICHA DEL PROYECTO
A3: Cliente
A4: Proyecto
A5: Código | B5: PA-001
A6: Ubicación
A7: Tipo de proyecto | B7: Remodelación
A8: Área del terreno (m²)
A9: Área construida existente (m²) | B9: 540
A10: Presupuesto referencial de obra (S/.)
A11: Fecha objetivo
A12: Estado actual | B12: Brief confirmado
A13: Responsable
A14: Fecha de levantamiento | B14: 46097

Sheet PROGRAMA ESPACIOS
A1: PROGRAMA DE ESPACIOS — MATRIZ
A3: Instrucción: cada fila es un espacio. Llena Zona, Espacio, Cantidad y Área unitaria; lo demás es opcional.
A5: Zona | B5: Espacio | C5: Cantidad | D5: Área unitaria (m²) | E5: Área total (m²) | F5: Usuarios | G5: Relación / adyacencia | H5: Prioridad | I5: Observaciones | J5: Orden (oculto) | K5: Zona (oculto) | M5: Cuadro de áreas por zona
E6: =IF(OR(C6="",D6=""),"",C6*D6) | J6: =IF(B6="","",VLOOKUP(A6,'LISTAS + README'!$A$11:$B$17,2,FALSE)*1000+ROW(A6)) | K6: =A6 -> 0 | M6: Zona | N6: Área (m²) | O6: %
E7: =IF(OR(C7="",D7=""),"",C7*D7) | J7: =IF(B7="","",VLOOKUP(A7,'LISTAS + README'!$A$11:$B$17,2,FALSE)*1000+ROW(A7)) | K7: =A7 -> 0 | M7: Pública | N7: =SUMIF($A$6:$A$55,M7,$E$6:$E$55) -> 0 | O7: =IF($N$14=0,"",N7/$N$14)
E8: =IF(OR(C8="",D8=""),"",C8*D8) | J8: =IF(B8="","",VLOOKUP(A8,'LISTAS + README'!$A$11:$B$17,2,FALSE)*1000+ROW(A8)) | K8: =A8 -> 0 | M8: Privada | N8: =SUMIF($A$6:$A$55,M8,$E$6:$E$55) -> 0 | O8: =IF($N$14=0,"",N8/$N$14)
E9: =IF(OR(C9="",D9=""),"",C9*D9) | J9: =IF(B9="","",VLOOKUP(A9,'LISTAS + README'!$A$11:$B$17,2,FALSE)*1000+ROW(A9)) | K9: =A9 -> 0 | M9: Servicio | N9: =SUMIF($A$6:$A$55,M9,$E$6:$E$55) -> 0 | O9: =IF($N$14=0,"",N9/$N$14)
E10: =IF(OR(C10="",D10=""),"",C10*D10) | J10: =IF(B10="","",VLOOKUP(A10,'LISTAS + README'!$A$11:$B$17,2,FALSE)*1000+ROW(A10)) | K10: =A10 -> 0 | M10: Exterior | N10: =SUMIF($A$6:$A$55,M10,$E$6:$E$55) -> 0 | O10: =IF($N$14=0,"",N10/$N$14)
E11: =IF(OR(C11="",D11=""),"",C11*D11) | J11: =IF(B11="","",VLOOKUP(A11,'LISTAS + README'!$A$11:$B$17,2,FALSE)*1000+ROW(A11)) | K11: =A11 -> 0 | M11: Técnica | N11: =SUMIF($A$6:$A$55,M11,$E$6:$E$55) -> 0 | O11: =IF($N$14=0,"",N11/$N$14)
E12: =IF(OR(C12="",D12=""),"",C12*D12) | J12: =IF(B12="","",VLOOKUP(A12,'LISTAS + README'!$A$11:$B$17,2,FALSE)*1000+ROW(A12)) | K12: =A12 -> 0 | M12: Comercial | N12: =SUMIF($A$6:$A$55,M12,$E$6:$E$55) -> 0 | O12: =IF($N$14=0,"",N12/$N$14)
E13: =IF(OR(C13="",D13=""),"",C13*D13) | J13: =IF(B13="","",VLOOKUP(A13,'LISTAS + README'!$A$11:$B$17,2,FALSE)*1000+ROW(A13)) | K13: =A13 -> 0 | M13: Común | N13: =SUMIF($A$6:$A$55,M13,$E$6:$E$55) -> 0 | O13: =IF($N$14=0,"",N13/$N$14)
E14: =IF(OR(C14="",D14=""),"",C14*D14) | J14: =IF(B14="","",VLOOKUP(A14,'LISTAS + README'!$A$11:$B$17,2,FALSE)*1000+ROW(A14)) | K14: =A14 -> 0 | M14: TOTAL | N14: =SUM(N7:N13) -> 0 | O14: 1
E15: =IF(OR(C15="",D15=""),"",C15*D15) | J15: =IF(B15="","",VLOOKUP(A15,'LISTAS + README'!$A$11:$B$17,2,FALSE)*1000+ROW(A15)) | K15: =A15 -> 0
E16: =IF(OR(C16="",D16=""),"",C16*D16) | J16: =IF(B16="","",VLOOKUP(A16,'LISTAS + README'!$A$11:$B$17,2,FALSE)*1000+ROW(A16)) | K16: =A16 -> 0
E17: =IF(OR(C17="",D17=""),"",C17*D17) | J17: =IF(B17="","",VLOOKUP(A17,'LISTAS + README'!$A$11:$B$17,2,FALSE)*1000+ROW(A17)) | K17: =A17 -> 0
E18: =IF(OR(C18="",D18=""),"",C18*D18) | J18: =IF(B18="","",VLOOKUP(A18,'LISTAS + README'!$A$11:$B$17,2,FALSE)*1000+ROW(A18)) | K18: =A18 -> 0
E19: =IF(OR(C19="",D19=""),"",C19*D19) | J19: =IF(B19="","",VLOOKUP(A19,'LISTAS + README'!$A$11:$B$17,2,FALSE)*1000+ROW(A19)) | K19: =A19 -> 0
E20: =IF(OR(C20="",D20=""),"",C20*D20) | J20: =IF(B20="","",VLOOKUP(A20,'LISTAS + README'!$A$11:$B$17,2,FALSE)*1000+ROW(A20)) | K20: =A20 -> 0
E21: =IF(OR(C21="",D21=""),"",C21*D21) | J21: =IF(B21="","",VLOOKUP(A21,'LISTAS + README'!$A$11:$B$17,2,FALSE)*1000+ROW(A21)) | K21: =A21 -> 0
E22: =IF(OR(C22="",D22=""),"",C22*D22) | J22: =IF(B22="","",VLOOKUP(A22,'LISTAS + README'!$A$11:$B$17,2,FALSE)*1000+ROW(A22)) | K22: =A22 -> 0
E23: =IF(OR(C23="",D23=""),"",C23*D23) | J23: =IF(B23="","",VLOOKUP(A23,'LISTAS + README'!$A$11:$B$17,2,FALSE)*1000+ROW(A23)) | K23: =A23 -> 0
E24: =IF(OR(C24="",D24=""),"",C24*D24) | J24: =IF(B24="","",VLOOKUP(A24,'LISTAS + README'!$A$11:$B$17,2,FALSE)*1000+ROW(A24)) | K24: =A24 -> 0
E25: =IF(OR(C25="",D25=""),"",C25*D25) | J25: =IF(B25="","",VLOOKUP(A25,'LISTAS + README'!$A$11:$B$17,2,FALSE)*1000+ROW(A25)) | K25: =A25 -> 0
E26: =IF(OR(C26="",D26=""),"",C26*D26) | J26: =IF(B26="","",VLOOKUP(A26,'LISTAS + README'!$A$11:$B$17,2,FALSE)*1000+ROW(A26)) | K26: =A26 -> 0
... E55: =IF(OR(C55="",D55=""),"",C55*D55) | J55: =IF(B55="","",VLOOKUP(A55,'LISTAS + README'!$A$11:$B$17,2,FALSE)*1000+ROW(A55)) | K55: =A55 -> 0

Sheet CONDICIONANTES
A1: CONDICIONANTES — RESTRICCIONES Y CRITERIOS
A3: Normativa y restricciones
A4: Normativa aplicable (municipal / condominio / interna)
A5: Parámetros urbanos (altura, retiros, ocupación, etc.)
A6: Restricciones del terreno / preexistencias
A7: Servidumbres / afectaciones / interferencias
A8: Permisos requeridos / revisiones externas
A10: Condicionantes técnicas
A11: Estado de estructura / muros / losas
A12: Instalaciones existentes (sanitaria, eléctrica, etc.)
A13: Limitaciones logísticas de obra (accesos, horarios)
A14: Seguridad y riesgos
... A22: Elementos deseados / no deseados

Sheet PRESENTACION
A1: FICHA DE BRIEF + PROGRAMA (LISTA PARA ADJUNTAR / FIRMAR)
A3: Datos generales
A4: Cliente | B4: =IF(IDENTIDAD!B3="","",IDENTIDAD!B3) | D4: Proyecto | E4: =IF(IDENTIDAD!B4="","",IDENTIDAD!B4)
A5: Código | B5: =IF(IDENTIDAD!B5="","",IDENTIDAD!B5) -> PA-001 | D5: Ubicación | E5: =IF(IDENTIDAD!B6="","",IDENTIDAD!B6)
A6: Tipo | B6: =IF(IDENTIDAD!B7="","",IDENTIDAD!B7) -> Remodelación | D6: Fecha objetivo | E6: =IF(IDENTIDAD!B11="","",IDENTIDAD!B11)
A7: Presupuesto obra | B7: =IF(IDENTIDAD!B10="","",IDENTIDAD!B10) | D7: Estado | E7: =IF(IDENTIDAD!B12="","",IDENTIDAD!B12) -> Brief confirmado
A9: Cuadro de áreas por zona
A10: Zona | B10: Área (m²) | C10: %
A11: Pública | B11: ='PROGRAMA ESPACIOS'!N7 -> 0 | C11: ='PROGRAMA ESPACIOS'!O7
A12: Privada | B12: ='PROGRAMA ESPACIOS'!N8 -> 0 | C12: ='PROGRAMA ESPACIOS'!O8
A13: Servicio | B13: ='PROGRAMA ESPACIOS'!N9 -> 0 | C13: ='PROGRAMA ESPACIOS'!O9
A14: Exterior | B14: ='PROGRAMA ESPACIOS'!N10 -> 0 | C14: ='PROGRAMA ESPACIOS'!O10
A15: Técnica | B15: ='PROGRAMA ESPACIOS'!N11 -> 0 | C15: ='PROGRAMA ESPACIOS'!O11
A16: Comercial | B16: ='PROGRAMA ESPACIOS'!N12 -> 0 | C16: ='PROGRAMA ESPACIOS'!O12
A17: Común | B17: ='PROGRAMA ESPACIOS'!N13 -> 0 | C17: ='PROGRAMA ESPACIOS'!O13
A18: TOTAL | B18: ='PROGRAMA ESPACIOS'!N14 -> 0 | C18: 1
A20: Programa de espacios (ordenado por zona)
A21: Zona | B21: Espacio | C21: Cant. | D21: Área u. | E21: Área T. | F21: Usuarios | G21: Relación | H21: Prior.
A22: =IFERROR(INDEX('PROGRAMA ESPACIOS'!$A$6:$A$55,MATCH(SMALL('PROGRAMA ESPACIOS'!$J$6:$J$55,1),'PROGRAMA ESPACIOS'!$J$6:$J$55,0)),"") | B22: =IF($A22="","",INDEX('PROGRAMA ESPACIOS'!$B$6:$B$55,MATCH(SMALL('PROGRAMA ESPACIOS'!$J$6:$J$55,1),'PROGRAMA ESPACIOS'!$J$6:$J$55,0))) | C22: =IF($A22="","",INDEX('PROGRAMA ESPACIOS'!$C$6:$C$55,MATCH(SMALL('PROGRAMA ESPACIOS'!$J$6:$J$55,1),'PROGRAMA ESPACIOS'!$J$6:$J$55,0))) | D22: =IF($A22="","",INDEX('PROGRAMA ESPACIOS'!$D$6:$D$55,MATCH(SMALL('PROGRAMA ESPACIOS'!$J$6:$J$55,1),'PROGRAMA ESPACIOS'!$J$6:$J$55,0))) | E22: =IF($A22="","",INDEX('PROGRAMA ESPACIOS'!$E$6:$E$55,MATCH(SMALL('PROGRAMA ESPACIOS'!$J$6:$J$55,1),'PROGRAMA ESPACIOS'!$J$6:$J$55,0))) | F22: =IF($A22="","",INDEX('PROGRAMA ESPACIOS'!$F$6:$F$55,MATCH(SMALL('PROGRAMA ESPACIOS'!$J$6:$J$55,1),'PROGRAMA ESPACIOS'!$J$6:$J$55,0))) | G22: =IF($A22="","",INDEX('PROGRAMA ESPACIOS'!$G$6:$G$55,MATCH(SMALL('PROGRAMA ESPACIOS'!$J$6:$J$55,1),'PROGRAMA ESPACIOS'!$J$6:$J$55,0))) | H22: =IF($A22="","",INDEX('PROGRAMA ESPACIOS'!$H$6:$H$55,MATCH(SMALL('PROGRAMA ESPACIOS'!$J$6:$J$55,1),'PROGRAMA ESPACIOS'!$J$6:$J$55,0)))
A23: =IFERROR(INDEX('PROGRAMA ESPACIOS'!$A$6:$A$55,MATCH(SMALL('PROGRAMA ESPACIOS'!$J$6:$J$55,2),'PROGRAMA ESPACIOS'!$J$6:$J$55,0)),"") | B23: =IF($A23="","",INDEX('PROGRAMA ESPACIOS'!$B$6:$B$55,MATCH(SMALL('PROGRAMA ESPACIOS'!$J$6:$J$55,2),'PROGRAMA ESPACIOS'!$J$6:$J$55,0))) | C23: =IF($A23="","",INDEX('PROGRAMA ESPACIOS'!$C$6:$C$55,MATCH(SMALL('PROGRAMA ESPACIOS'!$J$6:$J$55,2),'PROGRAMA ESPACIOS'!$J$6:$J$55,0))) | D23: =IF($A23="","",INDEX('PROGRAMA ESPACIOS'!$D$6:$D$55,MATCH(SMALL('PROGRAMA ESPACIOS'!$J$6:$J$55,2),'PROGRAMA ESPACIOS'!$J$6:$J$55,0))) | E23: =IF($A23="","",INDEX('PROGRAMA ESPACIOS'!$E$6:$E$55,MATCH(SMALL('PROGRAMA ESPACIOS'!$J$6:$J$55,2),'PROGRAMA ESPACIOS'!$J$6:$J$55,0))) | F23: =IF($A23="","",INDEX('PROGRAMA ESPACIOS'!$F$6:$F$55,MATCH(SMALL('PROGRAMA ESPACIOS'!$J$6:$J$55,2),'PROGRAMA ESPACIOS'!$J$6:$J$55,0))) | G23: =IF($A23="","",INDEX('PROGRAMA ESPACIOS'!$G$6:$G$55,MATCH(SMALL('PROGRAMA ESPACIOS'!$J$6:$J$55,2),'PROGRAMA ESPACIOS'!$J$6:$J$55,0))) | H23: =IF($A23="","",INDEX('PROGRAMA ESPACIOS'!$H$6:$H$55,MATCH(SMALL('PROGRAMA ESPACIOS'!$J$6:$J$55,2),'PROGRAMA ESPACIOS'!$J$6:$J$55,0)))
A24: =IFERROR(INDEX('PROGRAMA ESPACIOS'!$A$6:$A$55,MATCH(SMALL('PROGRAMA ESPACIOS'!$J$6:$J$55,3),'PROGRAMA ESPACIOS'!$J$6:$J$55,0)),"") | B24: =IF($A24="","",INDEX('PROGRAMA ESPACIOS'!$B$6:$B$55,MATCH(SMALL('PROGRAMA ESPACIOS'!$J$6:$J$55,3),'PROGRAMA ESPACIOS'!$J$6:$J$55,0))) | C24: =IF($A24="","",INDEX('PROGRAMA ESPACIOS'!$C$6:$C$55,MATCH(SMALL('PROGRAMA ESPACIOS'!$J$6:$J$55,3),'PROGRAMA ESPACIOS'!$J$6:$J$55,0))) | D24: =IF($A24="","",INDEX('PROGRAMA ESPACIOS'!$D$6:$D$55,MATCH(SMALL('PROGRAMA ESPACIOS'!$J$6:$J$55,3),'PROGRAMA ESPACIOS'!$J$6:$J$55,0))) | E24: =IF($A24="","",INDEX('PROGRAMA ESPACIOS'!$E$6:$E$55,MATCH(SMALL('PROGRAMA ESPACIOS'!$J$6:$J$55,3),'PROGRAMA ESPACIOS'!$J$6:$J$55,0))) | F24: =IF($A24="","",INDEX('PROGRAMA ESPACIOS'!$F$6:$F$55,MATCH(SMALL('PROGRAMA ESPACIOS'!$J$6:$J$55,3),'PROGRAMA ESPACIOS'!$J$6:$J$55,0))) | G24: =IF($A24="","",INDEX('PROGRAMA ESPACIOS'!$G$6:$G$55,MATCH(SMALL('PROGRAMA ESPACIOS'!$J$6:$J$55,3),'PROGRAMA ESPACIOS'!$J$6:$J$55,0))) | H24: =IF($A24="","",INDEX('PROGRAMA ESPACIOS'!$H$6:$H$55,MATCH(SMALL('PROGRAMA ESPACIOS'!$J$6:$J$55,3),'PROGRAMA ESPACIOS'!$J$6:$J$55,0)))
A25: =IFERROR(INDEX('PROGRAMA ESPACIOS'!$A$6:$A$55,MATCH(SMALL('PROGRAMA ESPACIOS'!$J$6:$J$55,4),'PROGRAMA ESPACIOS'!$J$6:$J$55,0)),"") | B25: =IF($A25="","",INDEX('PROGRAMA ESPACIOS'!$B$6:$B$55,MATCH(SMALL('PROGRAMA ESPACIOS'!$J$6:$J$55,4),'PROGRAMA ESPACIOS'!$J$6:$J$55,0))) | C25: =IF($A25="","",INDEX('PROGRAMA ESPACIOS'!$C$6:$C$55,MATCH(SMALL('PROGRAMA ESPACIOS'!$J$6:$J$55,4),'PROGRAMA ESPACIOS'!$J$6:$J$55,0))) | D25: =IF($A25="","",INDEX('PROGRAMA ESPACIOS'!$D$6:$D$55,MATCH(SMALL('PROGRAMA ESPACIOS'!$J$6:$J$55,4),'PROGRAMA ESPACIOS'!$J$6:$J$55,0))) | E25: =IF($A25="","",INDEX('PROGRAMA ESPACIOS'!$E$6:$E$55,MATCH(SMALL('PROGRAMA ESPACIOS'!$J$6:$J$55,4),'PROGRAMA ESPACIOS'!$J$6:$J$55,0))) | F25: =IF($A25="","",INDEX('PROGRAMA ESPACIOS'!$F$6:$F$55,MATCH(SMALL('PROGRAMA ESPACIOS'!$J$6:$J$55,4),'PROGRAMA ESPACIOS'!$J$6:$J$55,0))) | G25: =IF($A25="","",INDEX('PROGRAMA ESPACIOS'!$G$6:$G$55,MATCH(SMALL('PROGRAMA ESPACIOS'!$J$6:$J$55,4),'PROGRAMA ESPACIOS'!$J$6:$J$55,0))) | H25: =IF($A25="","",INDEX('PROGRAMA ESPACIOS'!$H$6:$H$55,MATCH(SMALL('PROGRAMA ESPACIOS'!$J$6:$J$55,4),'PROGRAMA ESPACIOS'!$J$6:$J$55,0)))
A26: =IFERROR(INDEX('PROGRAMA ESPACIOS'!$A$6:$A$55,MATCH(SMALL('PROGRAMA ESPACIOS'!$J$6:$J$55,5),'PROGRAMA ESPACIOS'!$J$6:$J$55,0)),"") | B26: =IF($A26="","",INDEX('PROGRAMA ESPACIOS'!$B$6:$B$55,MATCH(SMALL('PROGRAMA ESPACIOS'!$J$6:$J$55,5),'PROGRAMA ESPACIOS'!$J$6:$J$55,0))) | C26: =IF($A26="","",INDEX('PROGRAMA ESPACIOS'!$C$6:$C$55,MATCH(SMALL('PROGRAMA ESPACIOS'!$J$6:$J$55,5),'PROGRAMA ESPACIOS'!$J$6:$J$55,0))) | D26: =IF($A26="","",INDEX('PROGRAMA ESPACIOS'!$D$6:$D$55,MATCH(SMALL('PROGRAMA ESPACIOS'!$J$6:$J$55,5),'PROGRAMA ESPACIOS'!$J$6:$J$55,0))) | E26: =IF($A26="","",INDEX('PROGRAMA ESPACIOS'!$E$6:$E$55,MATCH(SMALL('PROGRAMA ESPACIOS'!$J$6:$J$55,5),'PROGRAMA ESPACIOS'!$J$6:$J$55,0))) | F26: =IF($A26="","",INDEX('PROGRAMA ESPACIOS'!$F$6:$F$55,MATCH(SMALL('PROGRAMA ESPACIOS'!$J$6:$J$55,5),'PROGRAMA ESPACIOS'!$J$6:$J$55,0))) | G26: =IF($A26="","",INDEX('PROGRAMA ESPACIOS'!$G$6:$G$55,MATCH(SMALL('PROGRAMA ESPACIOS'!$J$6:$J$55,5),'PROGRAMA ESPACIOS'!$J$6:$J$55,0))) | H26: =IF($A26="","",INDEX('PROGRAMA ESPACIOS'!$H$6:$H$55,MATCH(SMALL('PROGRAMA ESPACIOS'!$J$6:$J$55,5),'PROGRAMA ESPACIOS'!$J$6:$J$55,0)))
A27: =IFERROR(INDEX('PROGRAMA ESPACIOS'!$A$6:$A$55,MATCH(SMALL('PROGRAMA ESPACIOS'!$J$6:$J$55,6),'PROGRAMA ESPACIOS'!$J$6:$J$55,0)),"") | B27: =IF($A27="","",INDEX('PROGRAMA ESPACIOS'!$B$6:$B$55,MATCH(SMALL('PROGRAMA ESPACIOS'!$J$6:$J$55,6),'PROGRAMA ESPACIOS'!$J$6:$J$55,0))) | C27: =IF($A27="","",INDEX('PROGRAMA ESPACIOS'!$C$6:$C$55,MATCH(SMALL('PROGRAMA ESPACIOS'!$J$6:$J$55,6),'PROGRAMA ESPACIOS'!$J$6:$J$55,0))) | D27: =IF($A27="","",INDEX('PROGRAMA ESPACIOS'!$D$6:$D$55,MATCH(SMALL('PROGRAMA ESPACIOS'!$J$6:$J$55,6),'PROGRAMA ESPACIOS'!$J$6:$J$55,0))) | E27: =IF($A27="","",INDEX('PROGRAMA ESPACIOS'!$E$6:$E$55,MATCH(SMALL('PROGRAMA ESPACIOS'!$J$6:$J$55,6),'PROGRAMA ESPACIOS'!$J$6:$J$55,0))) | F27: =IF($A27="","",INDEX('PROGRAMA ESPACIOS'!$F$6:$F$55,MATCH(SMALL('PROGRAMA ESPACIOS'!$J$6:$J$55,6),'PROGRAMA ESPACIOS'!$J$6:$J$55,0))) | G27: =IF($A27="","",INDEX('PROGRAMA ESPACIOS'!$G$6:$G$55,MATCH(SMALL('PROGRAMA ESPACIOS'!$J$6:$J$55,6),'PROGRAMA ESPACIOS'!$J$6:$J$55,0))) | H27: =IF($A27="","",INDEX('PROGRAMA ESPACIOS'!$H$6:$H$55,MATCH(SMALL('PROGRAMA ESPACIOS'!$J$6:$J$55,6),'PROGRAMA ESPACIOS'!$J$6:$J$55,0)))
A28: =IFERROR(INDEX('PROGRAMA ESPACIOS'!$A$6:$A$55,MATCH(SMALL('PROGRAMA ESPACIOS'!$J$6:$J$55,7),'PROGRAMA ESPACIOS'!$J$6:$J$55,0)),"") | B28: =IF($A28="","",INDEX('PROGRAMA ESPACIOS'!$B$6:$B$55,MATCH(SMALL('PROGRAMA ESPACIOS'!$J$6:$J$55,7),'PROGRAMA ESPACIOS'!$J$6:$J$55,0))) | C28: =IF($A28="","",INDEX('PROGRAMA ESPACIOS'!$C$6:$C$55,MATCH(SMALL('PROGRAMA ESPACIOS'!$J$6:$J$55,7),'PROGRAMA ESPACIOS'!$J$6:$J$55,0))) | D28: =IF($A28="","",INDEX('PROGRAMA ESPACIOS'!$D$6:$D$55,MATCH(SMALL('PROGRAMA ESPACIOS'!$J$6:$J$55,7),'PROGRAMA ESPACIOS'!$J$6:$J$55,0))) | E28: =IF($A28="","",INDEX('PROGRAMA ESPACIOS'!$E$6:$E$55,MATCH(SMALL('PROGRAMA ESPACIOS'!$J$6:$J$55,7),'PROGRAMA ESPACIOS'!$J$6:$J$55,0))) | F28: =IF($A28="","",INDEX('PROGRAMA ESPACIOS'!$F$6:$F$55,MATCH(SMALL('PROGRAMA ESPACIOS'!$J$6:$J$55,7),'PROGRAMA ESPACIOS'!$J$6:$J$55,0))) | G28: =IF($A28="","",INDEX('PROGRAMA ESPACIOS'!$G$6:$G$55,MATCH(SMALL('PROGRAMA ESPACIOS'!$J$6:$J$55,7),'PROGRAMA ESPACIOS'!$J$6:$J$55,0))) | H28: =IF($A28="","",INDEX('PROGRAMA ESPACIOS'!$H$6:$H$55,MATCH(SMALL('PROGRAMA ESPACIOS'!$J$6:$J$55,7),'PROGRAMA ESPACIOS'!$J$6:$J$55,0)))
A29: =IFERROR(INDEX('PROGRAMA ESPACIOS'!$A$6:$A$55,MATCH(SMALL('PROGRAMA ESPACIOS'!$J$6:$J$55,8),'PROGRAMA ESPACIOS'!$J$6:$J$55,0)),"") | B29: =IF($A29="","",INDEX('PROGRAMA ESPACIOS'!$B$6:$B$55,MATCH(SMALL('PROGRAMA ESPACIOS'!$J$6:$J$55,8),'PROGRAMA ESPACIOS'!$J$6:$J$55,0))) | C29: =IF($A29="","",INDEX('PROGRAMA ESPACIOS'!$C$6:$C$55,MATCH(SMALL('PROGRAMA ESPACIOS'!$J$6:$J$55,8),'PROGRAMA ESPACIOS'!$J$6:$J$55,0))) | D29: =IF($A29="","",INDEX('PROGRAMA ESPACIOS'!$D$6:$D$55,MATCH(SMALL('PROGRAMA ESPACIOS'!$J$6:$J$55,8),'PROGRAMA ESPACIOS'!$J$6:$J$55,0))) | E29: =IF($A29="","",INDEX('PROGRAMA ESPACIOS'!$E$6:$E$55,MATCH(SMALL('PROGRAMA ESPACIOS'!$J$6:$J$55,8),'PROGRAMA ESPACIOS'!$J$6:$J$55,0))) | F29: =IF($A29="","",INDEX('PROGRAMA ESPACIOS'!$F$6:$F$55,MATCH(SMALL('PROGRAMA ESPACIOS'!$J$6:$J$55,8),'PROGRAMA ESPACIOS'!$J$6:$J$55,0))) | G29: =IF($A29="","",INDEX('PROGRAMA ESPACIOS'!$G$6:$G$55,MATCH(SMALL('PROGRAMA ESPACIOS'!$J$6:$J$55,8),'PROGRAMA ESPACIOS'!$J$6:$J$55,0))) | H29: =IF($A29="","",INDEX('PROGRAMA ESPACIOS'!$H$6:$H$55,MATCH(SMALL('PROGRAMA ESPACIOS'!$J$6:$J$55,8),'PROGRAMA ESPACIOS'!$J$6:$J$55,0)))
A30: =IFERROR(INDEX('PROGRAMA ESPACIOS'!$A$6:$A$55,MATCH(SMALL('PROGRAMA ESPACIOS'!$J$6:$J$55,9),'PROGRAMA ESPACIOS'!$J$6:$J$55,0)),"") | B30: =IF($A30="","",INDEX('PROGRAMA ESPACIOS'!$B$6:$B$55,MATCH(SMALL('PROGRAMA ESPACIOS'!$J$6:$J$55,9),'PROGRAMA ESPACIOS'!$J$6:$J$55,0))) | C30: =IF($A30="","",INDEX('PROGRAMA ESPACIOS'!$C$6:$C$55,MATCH(SMALL('PROGRAMA ESPACIOS'!$J$6:$J$55,9),'PROGRAMA ESPACIOS'!$J$6:$J$55,0))) | D30: =IF($A30="","",INDEX('PROGRAMA ESPACIOS'!$D$6:$D$55,MATCH(SMALL('PROGRAMA ESPACIOS'!$J$6:$J$55,9),'PROGRAMA ESPACIOS'!$J$6:$J$55,0))) | E30: =IF($A30="","",INDEX('PROGRAMA ESPACIOS'!$E$6:$E$55,MATCH(SMALL('PROGRAMA ESPACIOS'!$J$6:$J$55,9),'PROGRAMA ESPACIOS'!$J$6:$J$55,0))) | F30: =IF($A30="","",INDEX('PROGRAMA ESPACIOS'!$F$6:$F$55,MATCH(SMALL('PROGRAMA ESPACIOS'!$J$6:$J$55,9),'PROGRAMA ESPACIOS'!$J$6:$J$55,0))) | G30: =IF($A30="","",INDEX('PROGRAMA ESPACIOS'!$G$6:$G$55,MATCH(SMALL('PROGRAMA ESPACIOS'!$J$6:$J$55,9),'PROGRAMA ESPACIOS'!$J$6:$J$55,0))) | H30: =IF($A30="","",INDEX('PROGRAMA ESPACIOS'!$H$6:$H$55,MATCH(SMALL('PROGRAMA ESPACIOS'!$J$6:$J$55,9),'PROGRAMA ESPACIOS'!$J$6:$J$55,0)))
A31: =IFERROR(INDEX('PROGRAMA ESPACIOS'!$A$6:$A$55,MATCH(SMALL('PROGRAMA ESPACIOS'!$J$6:$J$55,10),'PROGRAMA ESPACIOS'!$J$6:$J$55,0)),"") | B31: =IF($A31="","",INDEX('PROGRAMA ESPACIOS'!$B$6:$B$55,MATCH(SMALL('PROGRAMA ESPACIOS'!$J$6:$J$55,10),'PROGRAMA ESPACIOS'!$J$6:$J$55,0))) | C31: =IF($A31="","",INDEX('PROGRAMA ESPACIOS'!$C$6:$C$55,MATCH(SMALL('PROGRAMA ESPACIOS'!$J$6:$J$55,10),'PROGRAMA ESPACIOS'!$J$6:$J$55,0))) | D31: =IF($A31="","",INDEX('PROGRAMA ESPACIOS'!$D$6:$D$55,MATCH(SMALL('PROGRAMA ESPACIOS'!$J$6:$J$55,10),'PROGRAMA ESPACIOS'!$J$6:$J$55,0))) | E31: =IF($A31="","",INDEX('PROGRAMA ESPACIOS'!$E$6:$E$55,MATCH(SMALL('PROGRAMA ESPACIOS'!$J$6:$J$55,10),'PROGRAMA ESPACIOS'!$J$6:$J$55,0))) | F31: =IF($A31="","",INDEX('PROGRAMA ESPACIOS'!$F$6:$F$55,MATCH(SMALL('PROGRAMA ESPACIOS'!$J$6:$J$55,10),'PROGRAMA ESPACIOS'!$J$6:$J$55,0))) | G31: =IF($A31="","",INDEX('PROGRAMA ESPACIOS'!$G$6:$G$55,MATCH(SMALL('PROGRAMA ESPACIOS'!$J$6:$J$55,10),'PROGRAMA ESPACIOS'!$J$6:$J$55,0))) | H31: =IF($A31="","",INDEX('PROGRAMA ESPACIOS'!$H$6:$H$55,MATCH(SMALL('PROGRAMA ESPACIOS'!$J$6:$J$55,10),'PROGRAMA ESPACIOS'!$J$6:$J$55,0)))
A32: =IFERROR(INDEX('PROGRAMA ESPACIOS'!$A$6:$A$55,MATCH(SMALL('PROGRAMA ESPACIOS'!$J$6:$J$55,11),'PROGRAMA ESPACIOS'!$J$6:$J$55,0)),"") | B32: =IF($A32="","",INDEX('PROGRAMA ESPACIOS'!$B$6:$B$55,MATCH(SMALL('PROGRAMA ESPACIOS'!$J$6:$J$55,11),'PROGRAMA ESPACIOS'!$J$6:$J$55,0))) | C32: =IF($A32="","",INDEX('PROGRAMA ESPACIOS'!$C$6:$C$55,MATCH(SMALL('PROGRAMA ESPACIOS'!$J$6:$J$55,11),'PROGRAMA ESPACIOS'!$J$6:$J$55,0))) | D32: =IF($A32="","",INDEX('PROGRAMA ESPACIOS'!$D$6:$D$55,MATCH(SMALL('PROGRAMA ESPACIOS'!$J$6:$J$55,11),'PROGRAMA ESPACIOS'!$J$6:$J$55,0))) | E32: =IF($A32="","",INDEX('PROGRAMA ESPACIOS'!$E$6:$E$55,MATCH(SMALL('PROGRAMA ESPACIOS'!$J$6:$J$55,11),'PROGRAMA ESPACIOS'!$J$6:$J$55,0))) | F32: =IF($A32="","",INDEX('PROGRAMA ESPACIOS'!$F$6:$F$55,MATCH(SMALL('PROGRAMA ESPACIOS'!$J$6:$J$55,11),'PROGRAMA ESPACIOS'!$J$6:$J$55,0))) | G32: =IF($A32="","",INDEX('PROGRAMA ESPACIOS'!$G$6:$G$55,MATCH(SMALL('PROGRAMA ESPACIOS'!$J$6:$J$55,11),'PROGRAMA ESPACIOS'!$J$6:$J$55,0))) | H32: =IF($A32="","",INDEX('PROGRAMA ESPACIOS'!$H$6:$H$55,MATCH(SMALL('PROGRAMA ESPACIOS'!$J$6:$J$55,11),'PROGRAMA ESPACIOS'!$J$6:$J$55,0)))
A33: =IFERROR(INDEX('PROGRAMA ESPACIOS'!$A$6:$A$55,MATCH(SMALL('PROGRAMA ESPACIOS'!$J$6:$J$55,12),'PROGRAMA ESPACIOS'!$J$6:$J$55,0)),"") | B33: =IF($A33="","",INDEX('PROGRAMA ESPACIOS'!$B$6:$B$55,MATCH(SMALL('PROGRAMA ESPACIOS'!$J$6:$J$55,12),'PROGRAMA ESPACIOS'!$J$6:$J$55,0))) | C33: =IF($A33="","",INDEX('PROGRAMA ESPACIOS'!$C$6:$C$55,MATCH(SMALL('PROGRAMA ESPACIOS'!$J$6:$J$55,12),'PROGRAMA ESPACIOS'!$J$6:$J$55,0))) | D33: =IF($A33="","",INDEX('PROGRAMA ESPACIOS'!$D$6:$D$55,MATCH(SMALL('PROGRAMA ESPACIOS'!$J$6:$J$55,12),'PROGRAMA ESPACIOS'!$J$6:$J$55,0))) | E33: =IF($A33="","",INDEX('PROGRAMA ESPACIOS'!$E$6:$E$55,MATCH(SMALL('PROGRAMA ESPACIOS'!$J$6:$J$55,12),'PROGRAMA ESPACIOS'!$J$6:$J$55,0))) | F33: =IF($A33="","",INDEX('PROGRAMA ESPACIOS'!$F$6:$F$55,MATCH(SMALL('PROGRAMA ESPACIOS'!$J$6:$J$55,12),'PROGRAMA ESPACIOS'!$J$6:$J$55,0))) | G33: =IF($A33="","",INDEX('PROGRAMA ESPACIOS'!$G$6:$G$55,MATCH(SMALL('PROGRAMA ESPACIOS'!$J$6:$J$55,12),'PROGRAMA ESPACIOS'!$J$6:$J$55,0))) | H33: =IF($A33="","",INDEX('PROGRAMA ESPACIOS'!$H$6:$H$55,MATCH(SMALL('PROGRAMA ESPACIOS'!$J$6:$J$55,12),'PROGRAMA ESPACIOS'!$J$6:$J$55,0)))
A34: =IFERROR(INDEX('PROGRAMA ESPACIOS'!$A$6:$A$55,MATCH(SMALL('PROGRAMA ESPACIOS'!$J$6:$J$55,13),'PROGRAMA ESPACIOS'!$J$6:$J$55,0)),"") | B34: =IF($A34="","",INDEX('PROGRAMA ESPACIOS'!$B$6:$B$55,MATCH(SMALL('PROGRAMA ESPACIOS'!$J$6:$J$55,13),'PROGRAMA ESPACIOS'!$J$6:$J$55,0))) | C34: =IF($A34="","",INDEX('PROGRAMA ESPACIOS'!$C$6:$C$55,MATCH(SMALL('PROGRAMA ESPACIOS'!$J$6:$J$55,13),'PROGRAMA ESPACIOS'!$J$6:$J$55,0))) | D34: =IF($A34="","",INDEX('PROGRAMA ESPACIOS'!$D$6:$D$55,MATCH(SMALL('PROGRAMA ESPACIOS'!$J$6:$J$55,13),'PROGRAMA ESPACIOS'!$J$6:$J$55,0))) | E34: =IF($A34="","",INDEX('PROGRAMA ESPACIOS'!$E$6:$E$55,MATCH(SMALL('PROGRAMA ESPACIOS'!$J$6:$J$55,13),'PROGRAMA ESPACIOS'!$J$6:$J$55,0))) | F34: =IF($A34="","",INDEX('PROGRAMA ESPACIOS'!$F$6:$F$55,MATCH(SMALL('PROGRAMA ESPACIOS'!$J$6:$J$55,13),'PROGRAMA ESPACIOS'!$J$6:$J$55,0))) | G34: =IF($A34="","",INDEX('PROGRAMA ESPACIOS'!$G$6:$G$55,MATCH(SMALL('PROGRAMA ESPACIOS'!$J$6:$J$55,13),'PROGRAMA ESPACIOS'!$J$6:$J$55,0))) | H34: =IF($A34="","",INDEX('PROGRAMA ESPACIOS'!$H$6:$H$55,MATCH(SMALL('PROGRAMA ESPACIOS'!$J$6:$J$55,13),'PROGRAMA ESPACIOS'!$J$6:$J$55,0)))
A35: =IFERROR(INDEX('PROGRAMA ESPACIOS'!$A$6:$A$55,MATCH(SMALL('PROGRAMA ESPACIOS'!$J$6:$J$55,14),'PROGRAMA ESPACIOS'!$J$6:$J$55,0)),"") | B35: =IF($A35="","",INDEX('PROGRAMA ESPACIOS'!$B$6:$B$55,MATCH(SMALL('PROGRAMA ESPACIOS'!$J$6:$J$55,14),'PROGRAMA ESPACIOS'!$J$6:$J$55,0))) | C35: =IF($A35="","",INDEX('PROGRAMA ESPACIOS'!$C$6:$C$55,MATCH(SMALL('PROGRAMA ESPACIOS'!$J$6:$J$55,14),'PROGRAMA ESPACIOS'!$J$6:$J$55,0))) | D35: =IF($A35="","",INDEX('PROGRAMA ESPACIOS'!$D$6:$D$55,MATCH(SMALL('PROGRAMA ESPACIOS'!$J$6:$J$55,14),'PROGRAMA ESPACIOS'!$J$6:$J$55,0))) | E35: =IF($A35="","",INDEX('PROGRAMA ESPACIOS'!$E$6:$E$55,MATCH(SMALL('PROGRAMA ESPACIOS'!$J$6:$J$55,14),'PROGRAMA ESPACIOS'!$J$6:$J$55,0))) | F35: =IF($A35="","",INDEX('PROGRAMA ESPACIOS'!$F$6:$F$55,MATCH(SMALL('PROGRAMA ESPACIOS'!$J$6:$J$55,14),'PROGRAMA ESPACIOS'!$J$6:$J$55,0))) | G35: =IF($A35="","",INDEX('PROGRAMA ESPACIOS'!$G$6:$G$55,MATCH(SMALL('PROGRAMA ESPACIOS'!$J$6:$J$55,14),'PROGRAMA ESPACIOS'!$J$6:$J$55,0))) | H35: =IF($A35="","",INDEX('PROGRAMA ESPACIOS'!$H$6:$H$55,MATCH(SMALL('PROGRAMA ESPACIOS'!$J$6:$J$55,14),'PROGRAMA ESPACIOS'!$J$6:$J$55,0)))
A36: =IFERROR(INDEX('PROGRAMA ESPACIOS'!$A$6:$A$55,MATCH(SMALL('PROGRAMA ESPACIOS'!$J$6:$J$55,15),'PROGRAMA ESPACIOS'!$J$6:$J$55,0)),"") | B36: =IF($A36="","",INDEX('PROGRAMA ESPACIOS'!$B$6:$B$55,MATCH(SMALL('PROGRAMA ESPACIOS'!$J$6:$J$55,15),'PROGRAMA ESPACIOS'!$J$6:$J$55,0))) | C36: =IF($A36="","",INDEX('PROGRAMA ESPACIOS'!$C$6:$C$55,MATCH(SMALL('PROGRAMA ESPACIOS'!$J$6:$J$55,15),'PROGRAMA ESPACIOS'!$J$6:$J$55,0))) | D36: =IF($A36="","",INDEX('PROGRAMA ESPACIOS'!$D$6:$D$55,MATCH(SMALL('PROGRAMA ESPACIOS'!$J$6:$J$55,15),'PROGRAMA ESPACIOS'!$J$6:$J$55,0))) | E36: =IF($A36="","",INDEX('PROGRAMA ESPACIOS'!$E$6:$E$55,MATCH(SMALL('PROGRAMA ESPACIOS'!$J$6:$J$55,15),'PROGRAMA ESPACIOS'!$J$6:$J$55,0))) | F36: =IF($A36="","",INDEX('PROGRAMA ESPACIOS'!$F$6:$F$55,MATCH(SMALL('PROGRAMA ESPACIOS'!$J$6:$J$55,15),'PROGRAMA ESPACIOS'!$J$6:$J$55,0))) | G36: =IF($A36="","",INDEX('PROGRAMA ESPACIOS'!$G$6:$G$55,MATCH(SMALL('PROGRAMA ESPACIOS'!$J$6:$J$55,15),'PROGRAMA ESPACIOS'!$J$6:$J$55,0))) | H36: =IF($A36="","",INDEX('PROGRAMA ESPACIOS'!$H$6:$H$55,MATCH(SMALL('PROGRAMA ESPACIOS'!$J$6:$J$55,15),'PROGRAMA ESPACIOS'!$J$6:$J$55,0)))
A37: =IFERROR(INDEX('PROGRAMA ESPACIOS'!$A$6:$A$55,MATCH(SMALL('PROGRAMA ESPACIOS'!$J$6:$J$55,16),'PROGRAMA ESPACIOS'!$J$6:$J$55,0)),"") | B37: =IF($A37="","",INDEX('PROGRAMA ESPACIOS'!$B$6:$B$55,MATCH(SMALL('PROGRAMA ESPACIOS'!$J$6:$J$55,16),'PROGRAMA ESPACIOS'!$J$6:$J$55,0))) | C37: =IF($A37="","",INDEX('PROGRAMA ESPACIOS'!$C$6:$C$55,MATCH(SMALL('PROGRAMA ESPACIOS'!$J$6:$J$55,16),'PROGRAMA ESPACIOS'!$J$6:$J$55,0))) | D37: =IF($A37="","",INDEX('PROGRAMA ESPACIOS'!$D$6:$D$55,MATCH(SMALL('PROGRAMA ESPACIOS'!$J$6:$J$55,16),'PROGRAMA ESPACIOS'!$J$6:$J$55,0))) | E37: =IF($A37="","",INDEX('PROGRAMA ESPACIOS'!$E$6:$E$55,MATCH(SMALL('PROGRAMA ESPACIOS'!$J$6:$J$55,16),'PROGRAMA ESPACIOS'!$J$6:$J$55,0))) | F37: =IF($A37="","",INDEX('PROGRAMA ESPACIOS'!$F$6:$F$55,MATCH(SMALL('PROGRAMA ESPACIOS'!$J$6:$J$55,16),'PROGRAMA ESPACIOS'!$J$6:$J$55,0))) | G37: =IF($A37="","",INDEX('PROGRAMA ESPACIOS'!$G$6:$G$55,MATCH(SMALL('PROGRAMA ESPACIOS'!$J$6:$J$55,16),'PROGRAMA ESPACIOS'!$J$6:$J$55,0))) | H37: =IF($A37="","",INDEX('PROGRAMA ESPACIOS'!$H$6:$H$55,MATCH(SMALL('PROGRAMA ESPACIOS'!$J$6:$J$55,16),'PROGRAMA ESPACIOS'!$J$6:$J$55,0)))
A38: =IFERROR(INDEX('PROGRAMA ESPACIOS'!$A$6:$A$55,MATCH(SMALL('PROGRAMA ESPACIOS'!$J$6:$J$55,17),'PROGRAMA ESPACIOS'!$J$6:$J$55,0)),"") | B38: =IF($A38="","",INDEX('PROGRAMA ESPACIOS'!$B$6:$B$55,MATCH(SMALL('PROGRAMA ESPACIOS'!$J$6:$J$55,17),'PROGRAMA ESPACIOS'!$J$6:$J$55,0))) | C38: =IF($A38="","",INDEX('PROGRAMA ESPACIOS'!$C$6:$C$55,MATCH(SMALL('PROGRAMA ESPACIOS'!$J$6:$J$55,17),'PROGRAMA ESPACIOS'!$J$6:$J$55,0))) | D38: =IF($A38="","",INDEX('PROGRAMA ESPACIOS'!$D$6:$D$55,MATCH(SMALL('PROGRAMA ESPACIOS'!$J$6:$J$55,17),'PROGRAMA ESPACIOS'!$J$6:$J$55,0))) | E38: =IF($A38="","",INDEX('PROGRAMA ESPACIOS'!$E$6:$E$55,MATCH(SMALL('PROGRAMA ESPACIOS'!$J$6:$J$55,17),'PROGRAMA ESPACIOS'!$J$6:$J$55,0))) | F38: =IF($A38="","",INDEX('PROGRAMA ESPACIOS'!$F$6:$F$55,MATCH(SMALL('PROGRAMA ESPACIOS'!$J$6:$J$55,17),'PROGRAMA ESPACIOS'!$J$6:$J$55,0))) | G38: =IF($A38="","",INDEX('PROGRAMA ESPACIOS'!$G$6:$G$55,MATCH(SMALL('PROGRAMA ESPACIOS'!$J$6:$J$55,17),'PROGRAMA ESPACIOS'!$J$6:$J$55,0))) | H38: =IF($A38="","",INDEX('PROGRAMA ESPACIOS'!$H$6:$H$55,MATCH(SMALL('PROGRAMA ESPACIOS'!$J$6:$J$55,17),'PROGRAMA ESPACIOS'!$J$6:$J$55,0)))
A39: =IFERROR(INDEX('PROGRAMA ESPACIOS'!$A$6:$A$55,MATCH(SMALL('PROGRAMA ESPACIOS'!$J$6:$J$55,18),'PROGRAMA ESPACIOS'!$J$6:$J$55,0)),"") | B39: =IF($A39="","",INDEX('PROGRAMA ESPACIOS'!$B$6:$B$55,MATCH(SMALL('PROGRAMA ESPACIOS'!$J$6:$J$55,18),'PROGRAMA ESPACIOS'!$J$6:$J$55,0))) | C39: =IF($A39="","",INDEX('PROGRAMA ESPACIOS'!$C$6:$C$55,MATCH(SMALL('PROGRAMA ESPACIOS'!$J$6:$J$55,18),'PROGRAMA ESPACIOS'!$J$6:$J$55,0))) | D39: =IF($A39="","",INDEX('PROGRAMA ESPACIOS'!$D$6:$D$55,MATCH(SMALL('PROGRAMA ESPACIOS'!$J$6:$J$55,18),'PROGRAMA ESPACIOS'!$J$6:$J$55,0))) | E39: =IF($A39="","",INDEX('PROGRAMA ESPACIOS'!$E$6:$E$55,MATCH(SMALL('PROGRAMA ESPACIOS'!$J$6:$J$55,18),'PROGRAMA ESPACIOS'!$J$6:$J$55,0))) | F39: =IF($A39="","",INDEX('PROGRAMA ESPACIOS'!$F$6:$F$55,MATCH(SMALL('PROGRAMA ESPACIOS'!$J$6:$J$55,18),'PROGRAMA ESPACIOS'!$J$6:$J$55,0))) | G39: =IF($A39="","",INDEX('PROGRAMA ESPACIOS'!$G$6:$G$55,MATCH(SMALL('PROGRAMA ESPACIOS'!$J$6:$J$55,18),'PROGRAMA ESPACIOS'!$J$6:$J$55,0))) | H39: =IF($A39="","",INDEX('PROGRAMA ESPACIOS'!$H$6:$H$55,MATCH(SMALL('PROGRAMA ESPACIOS'!$J$6:$J$55,18),'PROGRAMA ESPACIOS'!$J$6:$J$55,0)))
A40: =IFERROR(INDEX('PROGRAMA ESPACIOS'!$A$6:$A$55,MATCH(SMALL('PROGRAMA ESPACIOS'!$J$6:$J$55,19),'PROGRAMA ESPACIOS'!$J$6:$J$55,0)),"") | B40: =IF($A40="","",INDEX('PROGRAMA ESPACIOS'!$B$6:$B$55,MATCH(SMALL('PROGRAMA ESPACIOS'!$J$6:$J$55,19),'PROGRAMA ESPACIOS'!$J$6:$J$55,0))) | C40: =IF($A40="","",INDEX('PROGRAMA ESPACIOS'!$C$6:$C$55,MATCH(SMALL('PROGRAMA ESPACIOS'!$J$6:$J$55,19),'PROGRAMA ESPACIOS'!$J$6:$J$55,0))) | D40: =IF($A40="","",INDEX('PROGRAMA ESPACIOS'!$D$6:$D$55,MATCH(SMALL('PROGRAMA ESPACIOS'!$J$6:$J$55,19),'PROGRAMA ESPACIOS'!$J$6:$J$55,0))) | E40: =IF($A40="","",INDEX('PROGRAMA ESPACIOS'!$E$6:$E$55,MATCH(SMALL('PROGRAMA ESPACIOS'!$J$6:$J$55,19),'PROGRAMA ESPACIOS'!$J$6:$J$55,0))) | F40: =IF($A40="","",INDEX('PROGRAMA ESPACIOS'!$F$6:$F$55,MATCH(SMALL('PROGRAMA ESPACIOS'!$J$6:$J$55,19),'PROGRAMA ESPACIOS'!$J$6:$J$55,0))) | G40: =IF($A40="","",INDEX('PROGRAMA ESPACIOS'!$G$6:$G$55,MATCH(SMALL('PROGRAMA ESPACIOS'!$J$6:$J$55,19),'PROGRAMA ESPACIOS'!$J$6:$J$55,0))) | H40: =IF($A40="","",INDEX('PROGRAMA ESPACIOS'!$H$6:$H$55,MATCH(SMALL('PROGRAMA ESPACIOS'!$J$6:$J$55,19),'PROGRAMA ESPACIOS'!$J$6:$J$55,0)))
A41: =IFERROR(INDEX('PROGRAMA ESPACIOS'!$A$6:$A$55,MATCH(SMALL('PROGRAMA ESPACIOS'!$J$6:$J$55,20),'PROGRAMA ESPACIOS'!$J$6:$J$55,0)),"") | B41: =IF($A41="","",INDEX('PROGRAMA ESPACIOS'!$B$6:$B$55,MATCH(SMALL('PROGRAMA ESPACIOS'!$J$6:$J$55,20),'PROGRAMA ESPACIOS'!$J$6:$J$55,0))) | C41: =IF($A41="","",INDEX('PROGRAMA ESPACIOS'!$C$6:$C$55,MATCH(SMALL('PROGRAMA ESPACIOS'!$J$6:$J$55,20),'PROGRAMA ESPACIOS'!$J$6:$J$55,0))) | D41: =IF($A41="","",INDEX('PROGRAMA ESPACIOS'!$D$6:$D$55,MATCH(SMALL('PROGRAMA ESPACIOS'!$J$6:$J$55,20),'PROGRAMA ESPACIOS'!$J$6:$J$55,0))) | E41: =IF($A41="","",INDEX('PROGRAMA ESPACIOS'!$E$6:$E$55,MATCH(SMALL('PROGRAMA ESPACIOS'!$J$6:$J$55,20),'PROGRAMA ESPACIOS'!$J$6:$J$55,0))) | F41: =IF($A41="","",INDEX('PROGRAMA ESPACIOS'!$F$6:$F$55,MATCH(SMALL('PROGRAMA ESPACIOS'!$J$6:$J$55,20),'PROGRAMA ESPACIOS'!$J$6:$J$55,0))) | G41: =IF($A41="","",INDEX('PROGRAMA ESPACIOS'!$G$6:$G$55,MATCH(SMALL('PROGRAMA ESPACIOS'!$J$6:$J$55,20),'PROGRAMA ESPACIOS'!$J$6:$J$55,0))) | H41: =IF($A41="","",INDEX('PROGRAMA ESPACIOS'!$H$6:$H$55,MATCH(SMALL('PROGRAMA ESPACIOS'!$J$6:$J$55,20),'PROGRAMA ESPACIOS'!$J$6:$J$55,0)))
A43: Validación del cliente
A44: Firma: | E44: Nombre: ______________________
...
